<robot name="pend_robot">
  <gazebo>
	<plugin name="gazebo_ros_control" filename="libgazebo_ros_control.so">
	<robotNamespace>/pend</robotNamespace>
	  <robotSimType>gazebo_ros_control/DefaultRobotHWSim</robotSimType>
	</plugin>
</gazebo>

<link name="world"></link>

<!-- A simple fixed joint from our empty world link, to our base. -->
<!-- The base origin is offset from the world origin. -->
<joint name="base_joint" type="fixed">
    <origin xyz="0 0 0" rpy="0 0 0"/>
    <parent link="world"/>
    <child link="base_link"/>        
</joint>


  <gazebo reference="base_link">
    <material>Gazebo/Orange</material>
  </gazebo>
  <gazebo reference="body_link">
    <material>Gazebo/Red</material>
  </gazebo>

  <transmission name="tran1">
    <type>transmission_interface/SimpleTransmission</type>
    <joint name="motor_joint">
      <hardwareInterface>hardware_interface/EffortJointInterface</hardwareInterface>
    </joint>
    <actuator name="motor1">
      <hardwareInterface>hardware_interface/EffortJointInterface</hardwareInterface>
      <mechanicalReduction>1</mechanicalReduction>
    </actuator>
  </transmission>




 	<link name="base_link">
		<visual>
		    <origin xyz="0 0 0.0" rpy="0 0 0"/>
			<geometry>
				<cylinder radius="0.25" length="0.1"/>
			</geometry>          		
			<material name="Cyan1">
	       			<color rgba="0 0.9 0.9 1.0"/>
	     		</material>
		</visual>	
		<inertial>
			<mass value="100" />
	       		<origin xyz="0 0 0" rpy="0 0 0"/>
       			<inertia ixx="10"  ixy="0"  ixz="0" iyy="10" iyz="0" izz="10" />
    		</inertial>
	</link>
	
	<link name="body_link">
		<visual>
		    <origin xyz="0 0 0.60" rpy="0 0 0"/>
			<geometry>
				<cylinder radius="0.1" length="1.2"/>
			</geometry>
			<material name="Yellow1">
	       		<color rgba="0 0.0 0.9 1.0"/>
	     	</material>
		</visual>	
	</link>
	<link name="arm_link">
		<visual>
		    <origin xyz="0.0 0.0 0.40" rpy="0 0 0"/>
			<geometry>
				<cylinder radius="0.025" length="0.8"/>
			</geometry>
			<material name="Red1">
	       		<color rgba="0.5 0.0 0. 1.0"/>
	     	</material>
		</visual>	
	</link>
 	<link name="motor_link">
		<visual>
		    <origin xyz="0 0 0.10" rpy="0 0 0"/>
			<geometry>
				<cylinder radius="0.15" length="0.4"/>
			</geometry>
			<material name="Cyan1">
	       			<color rgba="0 0.9 0.9 1.0"/>
	     		</material>
		</visual>	
	</link>
	
  <link name="ball_link">
    <visual>
      <geometry>
        <sphere radius="0.1"/>
      </geometry>
      <material name="green">
            <color rgba="0 1 0 1"/>
      </material>     
    </visual>
    <inertial>
        <mass value="10" />
     	  <origin xyz="0 0 0" rpy="0 0 0"/>
    	  <inertia ixx="10"  ixy="0"  ixz="0" iyy="10" iyz="0" izz="10" />
      </inertial>
  </link>

	<joint name="first_joint" type="fixed">
    	<parent link="base_link"/>
    	<child link="body_link"/>
    	<origin xyz="0 0 0.00" rpy="0 0 0"/>
    	<axis xyz="0 0 1"/>
    	<limit lower="-3.1416" upper="3.1416" effort="10" velocity="3"/>
  	</joint>
  
 <joint name="motor_joint" type="revolute">
    	<parent link="body_link"/>
    	<child link="motor_link"/>
    	<origin xyz="0 0 1.20" rpy="0 1.5870 0"/>
    	<axis xyz="0 0 1"/>
    	<limit lower="-3.1416" upper="3.1416" effort="100" velocity="30"/>
	<dynamics damping="0.7"/>
	  	</joint>
 <joint name="arm_joint" type="fixed">
    	<parent link="motor_link"/>
    	<child link="arm_link"/>
    	<origin xyz="0 0 0.25" rpy="0 1.578 0"/>
    	<axis xyz="0 0 1"/>
    	<limit lower="-3.1416" upper="3.1416" effort="10" velocity="3"/>
  	</joint>
 <joint name="arm_joint2" type="fixed">
    	<parent link="arm_link"/>
    	<child link="ball_link"/>
    	<origin xyz="0 0 0.80" rpy="0 0 0"/>
    	<axis xyz="0 0 1"/>
    	<limit lower="-3.1416" upper="3.1416" effort="10" velocity="3"/>
  	</joint>

</robot>